<?xml version="1.0" ?>
<sdf version="1.8">
    <world name="car_world">
        <physics name="1ms" type="ignored">
            <max_step_size>0.001</max_step_size>
            <real_time_factor>1.0</real_time_factor>
        </physics>

        <plugin filename="gz-sim-physics-system" name="gz::sim::systems::Physics" />
        <plugin filename="gz-sim-user-commands-system" name="gz::sim::systems::UserCommands" />
        <plugin filename="gz-sim-scene-broadcaster-system" name="gz::sim::systems::SceneBroadcaster" />
        <plugin filename="gz-sim-sensors-system" name="gz::sim::systems::Sensors">
            <render_engine>ogre2</render_engine>
        </plugin>

        <plugin filename="gz-sim-triggered-publisher-system" name="gz::sim::systems::TriggeredPublisher">
            <input type="gz.msgs.Int32" topic="/keyboard/keypress">
                <match field="data">16777235</match>
            </input>
            <output type="gz.msgs.Twist" topic="/cmd_vel">
                linear: {x: 1.5}, angular: {z: 0.0}
            </output>
        </plugin>
        <plugin filename="gz-sim-triggered-publisher-system" name="gz::sim::systems::TriggeredPublisher">
            <input type="gz.msgs.Int32" topic="/keyboard/keypress">
                <match field="data">16777237</match>
            </input>
            <output type="gz.msgs.Twist" topic="/cmd_vel">
                linear: {x: -1.5}, angular: {z: 0.0}
            </output>
        </plugin>
        <plugin filename="gz-sim-triggered-publisher-system" name="gz::sim::systems::TriggeredPublisher">
            <input type="gz.msgs.Int32" topic="/keyboard/keypress">
                <match field="data">16777234</match>
            </input>
            <output type="gz.msgs.Twist" topic="/cmd_vel">
                linear: {x: 0.0}, angular: {z: 2.0}
            </output>
        </plugin>
        <plugin filename="gz-sim-triggered-publisher-system" name="gz::sim::systems::TriggeredPublisher">
            <input type="gz.msgs.Int32" topic="/keyboard/keypress">
                <match field="data">16777236</match>
            </input>
            <output type="gz.msgs.Twist" topic="/cmd_vel">
                linear: {x: 0.0}, angular: {z: -2.0}
            </output>
        </plugin>
        <plugin filename="gz-sim-triggered-publisher-system" name="gz::sim::systems::TriggeredPublisher">
            <input type="gz.msgs.Int32" topic="/keyboard/keypress">
                <match field="data">32</match>
            </input>
            <output type="gz.msgs.Twist" topic="/cmd_vel">
                linear: {x: 0.0}, angular: {z: 0.0}
            </output>
        </plugin>

        <light type="directional" name="sun">
            <cast_shadows>true</cast_shadows>
            <pose>0 0 10 0 0 0</pose>
            <diffuse>0.8 0.8 0.8 1</diffuse>
            <specular>0.2 0.2 0.2 1</specular>
            <direction>-0.5 0.1 -0.9</direction>
        </light>

        <model name="ground_plane">
            <static>true</static>
            <link name="link">
                <collision name="collision">
                    <geometry><plane><normal>0 0 1</normal><size>100 100</size></plane></geometry>
                </collision>
                <visual name="visual">
                    <geometry><plane><normal>0 0 1</normal><size>100 100</size></plane></geometry>
                    <material><ambient>0.8 0.8 0.8 1</ambient><diffuse>0.8 0.8 0.8 1</diffuse></material>
                </visual>
            </link>
        </model>

        <model name='box_obstacle'>
            <pose>4 0 0.5 0 0 0</pose>
            <link name='box_link'>
                <collision name='col'><geometry><box><size>1 1 1</size></box></geometry></collision>
                <visual name='vis'><geometry><box><size>1 1 1</size></box></geometry>
                    <material><ambient>1 0 0 1</ambient><diffuse>1 0 0 1</diffuse></material>
                </visual>
            </link>
        </model>

        <model name='cylinder_obstacle'>
            <pose>4 3 0.5 0 0 0</pose>
            <link name='cyl_link'>
                <collision name='col'><geometry><cylinder><radius>0.5</radius><length>1.0</length></cylinder></geometry></collision>
                <visual name='vis'><geometry><cylinder><radius>0.5</radius><length>1.0</length></cylinder></geometry>
                    <material><ambient>0 1 0 1</ambient><diffuse>0 1 0 1</diffuse></material>
                </visual>
            </link>
        </model>

        <model name='sphere_obstacle'>
            <pose>4 -3 0.5 0 0 0</pose>
            <link name='sph_link'>
                <collision name='col'><geometry><sphere><radius>0.5</radius></sphere></geometry></collision>
                <visual name='vis'><geometry><sphere><radius>0.5</radius></sphere></geometry>
                    <material><ambient>0 0 1 1</ambient><diffuse>0 0 1 1</diffuse></material>
                </visual>
            </link>
        </model>

        <model name='robot_4wd' canonical_link='chassis'>
            <pose relative_to='world'>0 0 0.6 0 0 0</pose>

            <link name='chassis'>
                <pose relative_to='__model__'>0.5 0 0.4 0 0 0</pose>
                <inertial>
                    <mass>1.14</mass>
                    <inertia><ixx>0.1</ixx><iyy>0.4</iyy><izz>0.5</izz></inertia>
                </inertial>
                <visual name='visual'>
                    <geometry><box><size>2.0 1.0 0.5</size></box></geometry>
                    <material><ambient>0.0 0.0 1.0 1</ambient><diffuse>0.0 0.0 1.0 1</diffuse></material>
                </visual>
                <collision name='collision'>
                    <geometry><box><size>2.0 1.0 0.5</size></box></geometry>
                </collision>
            </link>

            <link name='left_front_wheel'>
                <pose relative_to="chassis">0.8 0.6 0 -1.5707 0 0</pose>
                <inertial><mass>1</mass><inertia><ixx>0.04</ixx><iyy>0.04</iyy><izz>0.08</izz></inertia></inertial>
                <visual name='visual'><geometry><cylinder><radius>0.4</radius><length>0.2</length></cylinder></geometry>
                <material><ambient>0.2 0.2 0.2 1</ambient><diffuse>0.2 0.2 0.2 1</diffuse></material></visual>
                <collision name='collision'><geometry><cylinder><radius>0.4</radius><length>0.2</length></cylinder></geometry></collision>
            </link>
            <link name='left_rear_wheel'>
                <pose relative_to="chassis">-0.8 0.6 0 -1.5707 0 0</pose>
                <inertial><mass>1</mass><inertia><ixx>0.04</ixx><iyy>0.04</iyy><izz>0.08</izz></inertia></inertial>
                <visual name='visual'><geometry><cylinder><radius>0.4</radius><length>0.2</length></cylinder></geometry>
                <material><ambient>0.2 0.2 0.2 1</ambient><diffuse>0.2 0.2 0.2 1</diffuse></material></visual>
                <collision name='collision'><geometry><cylinder><radius>0.4</radius><length>0.2</length></cylinder></geometry></collision>
            </link>
            <link name='right_front_wheel'>
                <pose relative_to="chassis">0.8 -0.6 0 -1.5707 0 0</pose>
                <inertial><mass>1</mass><inertia><ixx>0.04</ixx><iyy>0.04</iyy><izz>0.08</izz></inertia></inertial>
                <visual name='visual'><geometry><cylinder><radius>0.4</radius><length>0.2</length></cylinder></geometry>
                <material><ambient>0.2 0.2 0.2 1</ambient><diffuse>0.2 0.2 0.2 1</diffuse></material></visual>
                <collision name='collision'><geometry><cylinder><radius>0.4</radius><length>0.2</length></cylinder></geometry></collision>
            </link>
            <link name='right_rear_wheel'>
                <pose relative_to="chassis">-0.8 -0.6 0 -1.5707 0 0</pose>
                <inertial><mass>1</mass><inertia><ixx>0.04</ixx><iyy>0.04</iyy><izz>0.08</izz></inertia></inertial>
                <visual name='visual'><geometry><cylinder><radius>0.4</radius><length>0.2</length></cylinder></geometry>
                <material><ambient>0.2 0.2 0.2 1</ambient><diffuse>0.2 0.2 0.2 1</diffuse></material></visual>
                <collision name='collision'><geometry><cylinder><radius>0.4</radius><length>0.2</length></cylinder></geometry></collision>
            </link>

            <joint name='left_front_wheel_joint' type='revolute'><parent>chassis</parent><child>left_front_wheel</child><axis><xyz>0 0 1</xyz></axis></joint>
            <joint name='left_rear_wheel_joint' type='revolute'><parent>chassis</parent><child>left_rear_wheel</child><axis><xyz>0 0 1</xyz></axis></joint>
            <joint name='right_front_wheel_joint' type='revolute'><parent>chassis</parent><child>right_front_wheel</child><axis><xyz>0 0 1</xyz></axis></joint>
            <joint name='right_rear_wheel_joint' type='revolute'><parent>chassis</parent><child>right_rear_wheel</child><axis><xyz>0 0 1</xyz></axis></joint>

            <link name='lidar_link'>
                <pose relative_to='chassis'>0.8 0 0.5 0 0 0</pose>
                <inertial><mass>0.1</mass><inertia><ixx>0.000166667</ixx><iyy>0.000166667</iyy><izz>0.000166667</izz></inertia></inertial>
                <visual name='visual'><geometry><cylinder><radius>0.05</radius><length>0.1</length></cylinder></geometry>
                <material><ambient>1 0 0 1</ambient><diffuse>1 0 0 1</diffuse></material></visual>
                <sensor name='gpu_lidar' type='gpu_lidar'>
                    <topic>lidar</topic>
                    <update_rate>10</update_rate>
                    <lidar>
                        <scan><horizontal><samples>640</samples><resolution>1</resolution>
                        <min_angle>-1.396263</min_angle><max_angle>1.396263</max_angle></horizontal></scan>
                        <range><min>0.08</min><max>10.0</max></range>
                    </lidar>
                    <visualize>true</visualize>
                </sensor>
            </link>
            <joint name='lidar_joint' type='fixed'><parent>chassis</parent><child>lidar_link</child></joint>

            <plugin filename="gz-sim-diff-drive-system" name="gz::sim::systems::DiffDrive">
                <left_joint>left_front_wheel_joint</left_joint>
                <left_joint>left_rear_wheel_joint</left_joint>
                <right_joint>right_front_wheel_joint</right_joint>
                <right_joint>right_rear_wheel_joint</right_joint>
                <wheel_separation>1.2</wheel_separation>
                <wheel_radius>0.4</wheel_radius>
                <topic>cmd_vel</topic>
                <max_linear_acceleration>10</max_linear_acceleration>
                <max_angular_acceleration>20</max_angular_acceleration>
            </plugin>
        </model>
    </world>
</sdf>
